Workbook

Sheet Hypothèses
C3: Luma Loop — Prévisionnel IAA Android
C5: Scénarios de revenus publicitaires récompensés — 12 mois
C6: USD, avant impôts, coûts d’acquisition, salaires et autres frais de Flash Digital SAS
C8: Indicateur | D8: Prudent | E8: Central | F8: Haut | G8: Méthode / source
C9: Nouvelles installations — mois 1 | D9: 100 | E9: 500 | F9: 2000 | G9: Hypothèse de distribution, sans campagne payante incluse.
C10: Nouvelles installations — mois 12 | D10: 800 | E10: 5000 | F10: 25000 | G10: Hypothèse de distribution, sans campagne payante incluse.
C11: Part des MAU précédents encore actifs | D11: 0.05 | E11: 0.1 | F11: 0.2 | G11: Hypothèse de rétention mensuelle simplifiée; non issue de données Luma Loop.
C12: DAU / MAU | D12: 0.08 | E12: 0.1 | F12: 0.15 | G12: Hypothèse de fréquence quotidienne; à remplacer par les données de production.
C13: Impressions récompensées par DAU / jour | D13: 0.3 | E13: 0.6 | F13: 1 | G13: Hypothèse de placement volontaire; aucune publicité n’est active dans la version 1.0.0.
C14: Taux de remplissage | D14: 0.8 | E14: 0.9 | F14: 0.95 | G14: Hypothèse de remplissage; dépend du pays, de la médiation et de la demande.
C15: eCPM rewarded | D15: 3 | E15: 5.1 | F15: 8 | G15: Scénario central : benchmark Android Europe de 5,10 USD; bornes prudente/haute : hypothèses de sensibilité.
C16: Jours par mois | D16: 30 | E16: 30 | F16: 30 | G16: Convention de modélisation uniforme sur 12 mois.
C19: Repère de marché
C20: Rétention mobile de référence | D20: Europe, médiane : D1 21,4 %, D7 4,31 %, D28 1,21 %
C21: eCPM Android Europe | D21: 5,10 USD pour vidéo récompensée selon le benchmark publié
C23: Formule de revenus
C24: Revenu mensuel | D24: DAU × 30 jours × opportunités rewarded/DAU/jour × fill rate × eCPM / 1 000
C25: Périmètre | D25: Modèle Android, publicité récompensée seulement, avant impôts et sans dépenses d’acquisition utilisateurs.

Sheet Prévision
C3: Luma Loop — Prévision de revenus IAA
C5: Calcul mensuel par scénario — hypothèses liées à l’onglet Hypothèses
C6: USD, revenus publicitaires estimés
C8: Prudent
C9: Mois | D9: Nouvelles installations | E9: MAU estimés | F9: DAU estimés | G9: Impressions rewarded | H9: Revenus IAA — Prudent
C10: 1 | D10: =Hypothèses!D9+(Hypothèses!D10-Hypothèses!D9)*($C10-1)/11 | E10: =D10 | F10: =E10*Hypothèses!D12 | G10: =F10*Hypothèses!D13*Hypothèses!D14*Hypothèses!D16 | H10: =G10*Hypothèses!D15/1000
C11: 2 | D11: =Hypothèses!D9+(Hypothèses!D10-Hypothèses!D9)*($C11-1)/11 | E11: =D11+E10*Hypothèses!D11 | F11: =E11*Hypothèses!D12 | G11: =F11*Hypothèses!D13*Hypothèses!D14*Hypothèses!D16 | H11: =G11*Hypothèses!D15/1000
C12: 3 | D12: =Hypothèses!D9+(Hypothèses!D10-Hypothèses!D9)*($C12-1)/11 | E12: =D12+E11*Hypothèses!D11 | F12: =E12*Hypothèses!D12 | G12: =F12*Hypothèses!D13*Hypothèses!D14*Hypothèses!D16 | H12: =G12*Hypothèses!D15/1000
C13: 4 | D13: =Hypothèses!D9+(Hypothèses!D10-Hypothèses!D9)*($C13-1)/11 | E13: =D13+E12*Hypothèses!D11 | F13: =E13*Hypothèses!D12 | G13: =F13*Hypothèses!D13*Hypothèses!D14*Hypothèses!D16 | H13: =G13*Hypothèses!D15/1000
C14: 5 | D14: =Hypothèses!D9+(Hypothèses!D10-Hypothèses!D9)*($C14-1)/11 | E14: =D14+E13*Hypothèses!D11 | F14: =E14*Hypothèses!D12 | G14: =F14*Hypothèses!D13*Hypothèses!D14*Hypothèses!D16 | H14: =G14*Hypothèses!D15/1000
C15: 6 | D15: =Hypothèses!D9+(Hypothèses!D10-Hypothèses!D9)*($C15-1)/11 | E15: =D15+E14*Hypothèses!D11 | F15: =E15*Hypothèses!D12 | G15: =F15*Hypothèses!D13*Hypothèses!D14*Hypothèses!D16 | H15: =G15*Hypothèses!D15/1000
C16: 7 | D16: =Hypothèses!D9+(Hypothèses!D10-Hypothèses!D9)*($C16-1)/11 | E16: =D16+E15*Hypothèses!D11 | F16: =E16*Hypothèses!D12 | G16: =F16*Hypothèses!D13*Hypothèses!D14*Hypothèses!D16 | H16: =G16*Hypothèses!D15/1000
C17: 8 | D17: =Hypothèses!D9+(Hypothèses!D10-Hypothèses!D9)*($C17-1)/11 | E17: =D17+E16*Hypothèses!D11 | F17: =E17*Hypothèses!D12 | G17: =F17*Hypothèses!D13*Hypothèses!D14*Hypothèses!D16 | H17: =G17*Hypothèses!D15/1000
C18: 9 | D18: =Hypothèses!D9+(Hypothèses!D10-Hypothèses!D9)*($C18-1)/11 | E18: =D18+E17*Hypothèses!D11 | F18: =E18*Hypothèses!D12 | G18: =F18*Hypothèses!D13*Hypothèses!D14*Hypothèses!D16 | H18: =G18*Hypothèses!D15/1000
C19: 10 | D19: =Hypothèses!D9+(Hypothèses!D10-Hypothèses!D9)*($C19-1)/11 | E19: =D19+E18*Hypothèses!D11 | F19: =E19*Hypothèses!D12 | G19: =F19*Hypothèses!D13*Hypothèses!D14*Hypothèses!D16 | H19: =G19*Hypothèses!D15/1000
C20: 11 | D20: =Hypothèses!D9+(Hypothèses!D10-Hypothèses!D9)*($C20-1)/11 | E20: =D20+E19*Hypothèses!D11 | F20: =E20*Hypothèses!D12 | G20: =F20*Hypothèses!D13*Hypothèses!D14*Hypothèses!D16 | H20: =G20*Hypothèses!D15/1000
C21: 12 | D21: =Hypothèses!D9+(Hypothèses!D10-Hypothèses!D9)*($C21-1)/11 | E21: =D21+E20*Hypothèses!D11 | F21: =E21*Hypothèses!D12 | G21: =F21*Hypothèses!D13*Hypothèses!D14*Hypothèses!D16 | H21: =G21*Hypothèses!D15/1000
C22: Total / moyenne | D22: =SUM(D10:D21) | E22: =AVERAGE(E10:E21) | F22: =AVERAGE(F10:F21) | G22: =SUM(G10:G21) | H22: =SUM(H10:H21)
C24: Central
C25: Mois | D25: Nouvelles installations | E25: MAU estimés | F25: DAU estimés | G25: Impressions rewarded | H25: Revenus IAA — Central
C26: 1 | D26: =Hypothèses!E9+(Hypothèses!E10-Hypothèses!E9)*($C26-1)/11 | E26: =D26 | F26: =E26*Hypothèses!E12 | G26: =F26*Hypothèses!E13*Hypothèses!E14*Hypothèses!E16 | H26: =G26*Hypothèses!E15/1000
C27: 2 | D27: =Hypothèses!E9+(Hypothèses!E10-Hypothèses!E9)*($C27-1)/11 | E27: =D27+E26*Hypothèses!E11 | F27: =E27*Hypothèses!E12 | G27: =F27*Hypothèses!E13*Hypothèses!E14*Hypothèses!E16 | H27: =G27*Hypothèses!E15/1000
C28: 3 | D28: =Hypothèses!E9+(Hypothèses!E10-Hypothèses!E9)*($C28-1)/11 | E28: =D28+E27*Hypothèses!E11 | F28: =E28*Hypothèses!E12 | G28: =F28*Hypothèses!E13*Hypothèses!E14*Hypothèses!E16 | H28: =G28*Hypothèses!E15/1000
C29: 4 | D29: =Hypothèses!E9+(Hypothèses!E10-Hypothèses!E9)*($C29-1)/11 | E29: =D29+E28*Hypothèses!E11 | F29: =E29*Hypothèses!E12 | G29: =F29*Hypothèses!E13*Hypothèses!E14*Hypothèses!E16 | H29: =G29*Hypothèses!E15/1000
C30: 5 | D30: =Hypothèses!E9+(Hypothèses!E10-Hypothèses!E9)*($C30-1)/11 | E30: =D30+E29*Hypothèses!E11 | F30: =E30*Hypothèses!E12 | G30: =F30*Hypothèses!E13*Hypothèses!E14*Hypothèses!E16 | H30: =G30*Hypothèses!E15/1000
C31: 6 | D31: =Hypothèses!E9+(Hypothèses!E10-Hypothèses!E9)*($C31-1)/11 | E31: =D31+E30*Hypothèses!E11 | F31: =E31*Hypothèses!E12 | G31: =F31*Hypothèses!E13*Hypothèses!E14*Hypothèses!E16 | H31: =G31*Hypothèses!E15/1000
C32: 7 | D32: =Hypothèses!E9+(Hypothèses!E10-Hypothèses!E9)*($C32-1)/11 | E32: =D32+E31*Hypothèses!E11 | F32: =E32*Hypothèses!E12 | G32: =F32*Hypothèses!E13*Hypothèses!E14*Hypothèses!E16 | H32: =G32*Hypothèses!E15/1000
C33: 8 | D33: =Hypothèses!E9+(Hypothèses!E10-Hypothèses!E9)*($C33-1)/11 | E33: =D33+E32*Hypothèses!E11 | F33: =E33*Hypothèses!E12 | G33: =F33*Hypothèses!E13*Hypothèses!E14*Hypothèses!E16 | H33: =G33*Hypothèses!E15/1000
C34: 9 | D34: =Hypothèses!E9+(Hypothèses!E10-Hypothèses!E9)*($C34-1)/11 | E34: =D34+E33*Hypothèses!E11 | F34: =E34*Hypothèses!E12 | G34: =F34*Hypothèses!E13*Hypothèses!E14*Hypothèses!E16 | H34: =G34*Hypothèses!E15/1000
C35: 10 | D35: =Hypothèses!E9+(Hypothèses!E10-Hypothèses!E9)*($C35-1)/11 | E35: =D35+E34*Hypothèses!E11 | F35: =E35*Hypothèses!E12 | G35: =F35*Hypothèses!E13*Hypothèses!E14*Hypothèses!E16 | H35: =G35*Hypothèses!E15/1000
C36: 11 | D36: =Hypothèses!E9+(Hypothèses!E10-Hypothèses!E9)*($C36-1)/11 | E36: =D36+E35*Hypothèses!E11 | F36: =E36*Hypothèses!E12 | G36: =F36*Hypothèses!E13*Hypothèses!E14*Hypothèses!E16 | H36: =G36*Hypothèses!E15/1000
C37: 12 | D37: =Hypothèses!E9+(Hypothèses!E10-Hypothèses!E9)*($C37-1)/11 | E37: =D37+E36*Hypothèses!E11 | F37: =E37*Hypothèses!E12 | G37: =F37*Hypothèses!E13*Hypothèses!E14*Hypothèses!E16 | H37: =G37*Hypothèses!E15/1000
C38: Total / moyenne | D38: =SUM(D26:D37) | E38: =AVERAGE(E26:E37) | F38: =AVERAGE(F26:F37) | G38: =SUM(G26:G37) | H38: =SUM(H26:H37)
C40: Haut
C41: Mois | D41: Nouvelles installations | E41: MAU estimés | F41: DAU estimés | G41: Impressions rewarded | H41: Revenus IAA — Haut
C42: 1 | D42: =Hypothèses!F9+(Hypothèses!F10-Hypothèses!F9)*($C42-1)/11 | E42: =D42 | F42: =E42*Hypothèses!F12 | G42: =F42*Hypothèses!F13*Hypothèses!F14*Hypothèses!F16 | H42: =G42*Hypothèses!F15/1000
C43: 2 | D43: =Hypothèses!F9+(Hypothèses!F10-Hypothèses!F9)*($C43-1)/11 | E43: =D43+E42*Hypothèses!F11 | F43: =E43*Hypothèses!F12 | G43: =F43*Hypothèses!F13*Hypothèses!F14*Hypothèses!F16 | H43: =G43*Hypothèses!F15/1000
C44: 3 | D44: =Hypothèses!F9+(Hypothèses!F10-Hypothèses!F9)*($C44-1)/11 | E44: =D44+E43*Hypothèses!F11 | F44: =E44*Hypothèses!F12 | G44: =F44*Hypothèses!F13*Hypothèses!F14*Hypothèses!F16 | H44: =G44*Hypothèses!F15/1000
C45: 4 | D45: =Hypothèses!F9+(Hypothèses!F10-Hypothèses!F9)*($C45-1)/11 | E45: =D45+E44*Hypothèses!F11 | F45: =E45*Hypothèses!F12 | G45: =F45*Hypothèses!F13*Hypothèses!F14*Hypothèses!F16 | H45: =G45*Hypothèses!F15/1000
C46: 5 | D46: =Hypothèses!F9+(Hypothèses!F10-Hypothèses!F9)*($C46-1)/11 | E46: =D46+E45*Hypothèses!F11 | F46: =E46*Hypothèses!F12 | G46: =F46*Hypothèses!F13*Hypothèses!F14*Hypothèses!F16 | H46: =G46*Hypothèses!F15/1000
...

Sheet Synthèse
C3: Luma Loop — Synthèse du prévisionnel IAA
C5: Vue de décision : publicité récompensée Android uniquement
C6: USD, avant impôts et dépenses de Flash Digital SAS
C8: Indicateur | D8: Prudent | E8: Central | F8: Haut
C9: Installations cumulées à 12 mois | D9: =Prévision!D22 | E9: =Prévision!D38 | F9: =Prévision!D54
C10: DAU moyen à 12 mois | D10: =Prévision!F22 | E10: =Prévision!F38 | F10: =Prévision!F54
C11: Revenu IAA total, 12 mois | D11: =Prévision!H22 | E11: =Prévision!H38 | F11: =Prévision!H54
C12: Revenu IAA du mois 12 | D12: =Prévision!H21 | E12: =Prévision!H37 | F12: =Prévision!H53
C13: DAU requis pour 1 000 USD / mois | D13: =1000*1000/(Hypothèses!D13*Hypothèses!D14*Hypothèses!D15*Hypothèses!D16) | E13: =1000*1000/(Hypothèses!E13*Hypothèses!E14*Hypothèses!E15*Hypothèses!E16) | F13: =1000*1000/(Hypothèses!F13*Hypothèses!F14*Hypothèses!F15*Hypothèses!F16)
C14: DAU requis pour 10 000 USD / mois | D14: =D13*10 | E14: =E13*10 | F14: =F13*10
C17: Lecture de décision
C18: La publicité récompensée est une option de monétisation, pas une garantie de revenus. Dans ce modèle, le principal levier est le DAU durable : les revenus ne deviennent significatifs qu’à une audience régulière de plusieurs milliers de DAU.
C21: Recommandation produit
C22: Publier 1.0.0 sans publicité, mesurer acquisition et rétention, puis tester dans une mise à jour une seule publicité récompensée volontaire à un moment de pause naturel. Éviter bannières et interstitiels dans la boucle de jeu.
